<?xml version="1.0" encoding="utf-8"?>
<!-- This URDF was automatically created by SolidWorks to URDF Exporter! Originally created by Stephen Brawner (brawner@gmail.com) 
     Commit Version: 1.6.0-4-g7f85cfe  Build Version: 1.6.7995.38578
     For more information, please see http://wiki.ros.org/sw_urdf_exporter -->
<robot
  name="brazorobot_actualizado">
  <link name="world"/>
    <joint name="base_joint" type="fixed">
    <parent link="world"/>
    <child link="base_link"/>
    <origin rpy="0 0 0" xyz="0.0 0.0 0.17"/>
  </joint>

  <link
    name="link_1">
    <inertial>
      <origin
        xyz="-0.00882290273067091 0 0.0269217585658854"
        rpy="0 0 0" />
      <mass
        value="0.335288318064784" />
      <inertia
        ixx="0.000301882076882298"
        ixy="-2.37222794563191E-20"
        ixz="1.52482939379535E-05"
        iyy="0.000465085576680723"
        iyz="-1.78618046858673E-20"
        izz="0.000536871509489116" />
    </inertial>
    <visual>
      <origin
        xyz="0 0 0"
        rpy="0 0 0" />
      <geometry>
        <mesh
          filename="package://brazorobot_actualizado/meshes/link_1.STL" />
      </geometry>
      <material
        name="">
        <color
          rgba="1 1 1 1" />
      </material>
    </visual>
    <collision>
      <origin
        xyz="0 0 0"
        rpy="0 0 0" />
      <geometry>
        <mesh
          filename="package://brazorobot_actualizado/meshes/link_1.STL" />
      </geometry>
    </collision>
  </link>
  <link
    name="link_2">
    <inertial>
      <origin
        xyz="0 0 0.0630288606936914"
        rpy="0 0 0" />
      <mass
        value="0.00792631563306555" />
      <inertia
        ixx="9.54333718723177E-07"
        ixy="-1.32122335786909E-23"
        ixz="4.18667533966378E-23"
        iyy="9.71075618241566E-07"
        iyz="2.03729901633582E-23"
        izz="7.97669672938977E-07" />
    </inertial>
    <visual>
      <origin
        xyz="0 0 0"
        rpy="0 0 0" />
      <geometry>
        <mesh
          filename="package://brazorobot_actualizado/meshes/link_2.STL" />
      </geometry>
      <material
        name="">
        <color
          rgba="1 1 1 1" />
      </material>
    </visual>
    <collision>
      <origin
        xyz="0 0 0"
        rpy="0 0 0" />
      <geometry>
        <mesh
          filename="package://brazorobot_actualizado/meshes/link_2.STL" />
      </geometry>
    </collision>
  </link>
  <joint
    name="joint_1"
    type="revolute">
    <origin
      xyz="0 0 0"
      rpy="0 0 0" />
    <parent
      link="link_1" />
    <child
      link="link_2" />
    <axis
      xyz="0 0 -1" />
    <limit
      lower="-1.5708"
      upper="1.5708"
      effort="0.18"
      velocity="10.472" />
    <dynamics
      damping="0"
      friction="0" />
  </joint>
  <link
    name="link_3">
    <inertial>
      <origin
        xyz="-0.000966415503477563 -0.0190572854817526 0.00105821743021271"
        rpy="0 0 0" />
      <mass
        value="0.0485744385999758" />
      <inertia
        ixx="1.8593970179839E-05"
        ixy="-5.25312085428344E-07"
        ixz="-1.31826405070508E-07"
        iyy="3.2725311613632E-06"
        iyz="1.54876095792427E-06"
        izz="1.9702766411215E-05" />
    </inertial>
    <visual>
      <origin
        xyz="0 0 0"
        rpy="0 0 0" />
      <geometry>
        <mesh
          filename="package://brazorobot_actualizado/meshes/link_3.STL" />
      </geometry>
      <material
        name="">
        <color
          rgba="1 1 1 1" />
      </material>
    </visual>
    <collision>
      <origin
        xyz="0 0 0"
        rpy="0 0 0" />
      <geometry>
        <mesh
          filename="package://brazorobot_actualizado/meshes/link_3.STL" />
      </geometry>
    </collision>
  </link>
  <joint
    name="joint_3"
    type="revolute">
    <origin
      xyz="0 0 0.075"
      rpy="-1.5708 0 0" />
    <parent
      link="link_2" />
    <child
      link="link_3" />
    <axis
      xyz="0 0 -1" />
    <limit
      lower="-1.5708"
      upper="1.5708"
      effort="0.18"
      velocity="10.472" />
    <dynamics
      damping="0"
      friction="0" />
  </joint>
  <link
    name="link_4">
    <inertial>
      <origin
        xyz="0.000301769617941816 0.0299293457414871 -0.000556617692094648"
        rpy="0 0 0" />
      <mass
        value="0.028486686920439" />
      <inertia
        ixx="1.51704938602305E-05"
        ixy="-1.96328794398074E-08"
        ixz="-5.85124985696709E-08"
        iyy="1.87208865570457E-06"
        iyz="-2.12186863467087E-07"
        izz="1.59205662534004E-05" />
    </inertial>
    <visual>
      <origin
        xyz="0 0 0"
        rpy="0 0 0" />
      <geometry>
        <mesh
          filename="package://brazorobot_actualizado/meshes/link_4.STL" />
      </geometry>
      <material
        name="">
        <color
          rgba="1 1 1 1" />
      </material>
    </visual>
    <collision>
      <origin
        xyz="0 0 0"
        rpy="0 0 0" />
      <geometry>
        <mesh
          filename="package://brazorobot_actualizado/meshes/link_4.STL" />
      </geometry>
    </collision>
  </link>
  <joint
    name="joint_4"
    type="revolute">
    <origin
      xyz="0 -0.06 0"
      rpy="0 0 -1.5708" />
    <parent
      link="link_3" />
    <child
      link="link_4" />
    <axis
      xyz="0 0 -1" />
    <limit
      lower="0"
      upper="3.1416"
      effort="0.18"
      velocity="10.472" />
    <dynamics
      damping="0"
      friction="0" />
  </joint>
  <link
    name="link_5">
    <inertial>
      <origin
        xyz="-0.00104217230985984 3.44390048610879E-05 0.0812317135361134"
        rpy="0 0 0" />
      <mass
        value="0.00437816277547282" />
      <inertia
        ixx="3.8534696570901E-07"
        ixy="4.83674876889537E-10"
        ixz="5.5601554146915E-08"
        iyy="3.84305888855166E-07"
        iyz="-1.83737581149913E-09"
        izz="1.93040520057411E-07" />
    </inertial>
    <visual>
      <origin
        xyz="0 0 0"
        rpy="0 0 0" />
      <geometry>
        <mesh
          filename="package://brazorobot_actualizado/meshes/link_5.STL" />
      </geometry>
      <material
        name="">
        <color
          rgba="1 1 1 1" />
      </material>
    </visual>
    <collision>
      <origin
        xyz="0 0 0"
        rpy="0 0 0" />
      <geometry>
        <mesh
          filename="package://brazorobot_actualizado/meshes/link_5.STL" />
      </geometry>
    </collision>
  </link>
  <joint
    name="joint_5"
    type="revolute">
    <origin
      xyz="0 0 0"
      rpy="-1.5708 0 0" />
    <parent
      link="link_4" />
    <child
      link="link_5" />
    <axis
      xyz="0 0 -1" />
    <limit
      lower="-1.5708"
      upper="1.5708"
      effort="0.18"
      velocity="10.472" />
    <dynamics
      damping="0"
      friction="0" />
  </joint>
  <link
    name="link_6">
    <inertial>
      <origin
        xyz="0.00167592221045527 -0.0088511242428389 -0.00127020520761781"
        rpy="0 0 0" />
      <mass
        value="0.000226797486557845" />
      <inertia
        ixx="1.24300680379589E-08"
        ixy="-1.37850376202537E-09"
        ixz="-2.15132336678204E-22"
        iyy="1.44598497176332E-09"
        iyz="-3.96593691468018E-22"
        izz="1.35570478126575E-08" />
    </inertial>
    <visual>
      <origin
        xyz="0 0 0"
        rpy="0 0 0" />
      <geometry>
        <mesh
          filename="package://brazorobot_actualizado/meshes/link_6.STL" />
      </geometry>
      <material
        name="">
        <color
          rgba="1 1 1 1" />
      </material>
    </visual>
    <collision>
      <origin
        xyz="0 0 0"
        rpy="0 0 0" />
      <geometry>
        <mesh
          filename="package://brazorobot_actualizado/meshes/link_6.STL" />
      </geometry>
    </collision>
  </link>
  <joint
    name="joint_6"
    type="revolute">
    <origin
      xyz="0 -0.0036696 0.099465"
      rpy="-1.5708 0 -1.5708" />
    <parent
      link="link_5" />
    <child
      link="link_6" />
    <axis
      xyz="0 0 -1" />
    <limit
      lower="-1.5708"
      upper="0"
      effort="0.18"
      velocity="10.472" />
    <dynamics
      damping="0"
      friction="0" />
  </joint>
  <link
    name="link_7">
    <inertial>
      <origin
        xyz="0.0017313 -0.0088405 0.0012702"
        rpy="0 0 0" />
      <mass
        value="0.0002268" />
      <inertia
        ixx="1.2447E-08"
        ixy="-1.3096E-09"
        ixz="-1.1873E-22"
        iyy="1.4292E-09"
        iyz="6.2202E-23"
        izz="1.3557E-08" />
    </inertial>
    <visual>
      <origin
        xyz="0 0 0"
        rpy="0 0 0" />
      <geometry>
        <mesh
          filename="package://brazorobot_actualizado/meshes/link_7.STL" />
      </geometry>
      <material
        name="">
        <color
          rgba="1 1 1 1" />
      </material>
    </visual>
    <collision>
      <origin
        xyz="0 0 0"
        rpy="0 0 0" />
      <geometry>
        <mesh
          filename="package://brazorobot_actualizado/meshes/link_7.STL" />
      </geometry>
    </collision>
  </link>
  <joint
    name="joint_7"
    type="revolute">
    <origin
      xyz="0 0.0039504 0.099465"
      rpy="-1.5708 0 1.5708" />
    <parent
      link="link_5" />
    <child
      link="link_7" />
    <axis
      xyz="0 0 1" />
    <limit
      lower="0"
      upper="1.5708"
      effort="0.18"
      velocity="10.472" />
    <dynamics
      damping="0"
      friction="0" />
    <mimic
      joint="joint_6"
      multiplier="1"
      offset="0" />
  </joint>

  
  <transmission name="link_2_trans">
    <type>transmission_interface/SimpleTransmission</type>
    <joint name="joint_1">
    <hardwareInterface>hardware_interface/PositionJointInterface</hardwareInterface></joint>
    <actuator name="link_2_motor">
    <hardwareInterface>hardware_interface/PositionJointInterface</hardwareInterface> <mechanicalReduction>1</mechanicalReduction>
    </actuator>
  </transmission>
  <gazebo>
    <plugin name="control"
    filename="libgazebo_ros_control.so">
    <robotNamespace>/</robotNamespace>
    </plugin>
  </gazebo>

  <gazebo reference="link_2">
    <selfCollide>true</selfCollide>
  </gazebo>

  <transmission name="link_3_trans">
    <type>transmission_interface/SimpleTransmission</type>
    <joint name="joint_3">
    <hardwareInterface>hardware_interface/PositionJointInterface</hardwareInterface></joint>
    <actuator name="link_3_motor">
    <hardwareInterface>hardware_interface/PositionJointInterface</hardwareInterface> <mechanicalReduction>1</mechanicalReduction>
    </actuator>
  </transmission>
  <gazebo>
    <plugin name="control"
    filename="libgazebo_ros_control.so">
    <robotNamespace>/</robotNamespace>
    </plugin>
  </gazebo>

  <gazebo reference="link_3">
    <selfCollide>true</selfCollide>
  </gazebo>

  <transmission name="link_4_trans">
    <type>transmission_interface/SimpleTransmission</type>
    <joint name="joint_4">
    <hardwareInterface>hardware_interface/PositionJointInterface</hardwareInterface></joint>
    <actuator name="link_4_motor">
    <hardwareInterface>hardware_interface/PositionJointInterface</hardwareInterface> <mechanicalReduction>1</mechanicalReduction>
    </actuator>
  </transmission>
  <gazebo>
    <plugin name="control"
    filename="libgazebo_ros_control.so">
    <robotNamespace>/</robotNamespace>
    </plugin>
  </gazebo>

  <gazebo reference="link_4">
    <selfCollide>true</selfCollide>
  </gazebo>

  <transmission name="link_5_trans">
    <type>transmission_interface/SimpleTransmission</type>
    <joint name="joint_5">
    <hardwareInterface>hardware_interface/PositionJointInterface</hardwareInterface></joint>
    <actuator name="link_5_motor">
    <hardwareInterface>hardware_interface/PositionJointInterface</hardwareInterface> <mechanicalReduction>1</mechanicalReduction>
    </actuator>
  </transmission>
  <gazebo>
    <plugin name="control"
    filename="libgazebo_ros_control.so">
    <robotNamespace>/</robotNamespace>
    </plugin>
  </gazebo>

  <gazebo reference="link_5">
    <selfCollide>true</selfCollide>
  </gazebo>

  <transmission name="link_6_trans">
    <type>transmission_interface/SimpleTransmission</type>
    <joint name="joint_6">
    <hardwareInterface>hardware_interface/PositionJointInterface</hardwareInterface></joint>
    <actuator name="link_6_motor">
    <hardwareInterface>hardware_interface/PositionJointInterface</hardwareInterface> <mechanicalReduction>1</mechanicalReduction>
    </actuator>
  </transmission>
  <gazebo>
    <plugin name="control"
    filename="libgazebo_ros_control.so">
    <robotNamespace>/</robotNamespace>
    </plugin>
  </gazebo>

  <gazebo reference="link_6">
    <selfCollide>true</selfCollide>
  </gazebo>

  <transmission name="link7_trans">
    <type>transmission_interface/SimpleTransmission</type>
    <joint name="joint_7">
    <hardwareInterface>hardware_interface/PositionJointInterface</hardwareInterface></joint>
    <actuator name="link_7_motor">
    <hardwareInterface>hardware_interface/PositionJointInterface</hardwareInterface> <mechanicalReduction>1</mechanicalReduction>
    </actuator>
  </transmission>
  <gazebo>
    <plugin name="control"
    filename="libgazebo_ros_control.so">
    <robotNamespace>/</robotNamespace>
    </plugin>
  </gazebo>

  <gazebo reference="link_7">
    <selfCollide>true</selfCollide>
  </gazebo>

</robot>