<?xml version="1.0" encoding="utf-8"?>
<!-- This URDF was automatically created by SolidWorks to URDF Exporter! Originally created by Stephen Brawner (brawner@gmail.com) 
     Commit Version: 1.6.0-4-g7f85cfe  Build Version: 1.6.7995.38578
     For more information, please see http://wiki.ros.org/sw_urdf_exporter -->
<robot
  name="BRAZO_ROBOT_URDF">
  <link
    name="eslabon base">
    <inertial>
      <origin
        xyz="-0.0088229 -6.9389E-18 0.026922"
        rpy="0 0 0" />
      <mass
        value="0.33529" />
      <inertia
        ixx="0.00030188"
        ixy="-2.3722E-20"
        ixz="1.5248E-05"
        iyy="0.00046509"
        iyz="-1.7862E-20"
        izz="0.00053687" />
    </inertial>
    <visual>
      <origin
        xyz="0 0 0"
        rpy="0 0 0" />
      <geometry>
        <mesh
          filename="package://BRAZO_ROBOT_URDF/meshes/eslabon base.STL" />
      </geometry>
      <material
        name="">
        <color
          rgba="1 1 1 1" />
      </material>
    </visual>
    <collision>
      <origin
        xyz="0 0 0"
        rpy="0 0 0" />
      <geometry>
        <mesh
          filename="package://BRAZO_ROBOT_URDF/meshes/eslabon base.STL" />
      </geometry>
    </collision>
  </link>
  <link
    name="ESLABON ROTACION">
    <inertial>
      <origin
        xyz="1.38777878078145E-17 0 0.0630288606936914"
        rpy="0 0 0" />
      <mass
        value="0.00792631563306555" />
      <inertia
        ixx="9.54333718723177E-07"
        ixy="-1.48793855574928E-23"
        ixz="3.26354663080921E-23"
        iyy="9.71075618241566E-07"
        iyz="-2.63461630643741E-23"
        izz="7.97669672938977E-07" />
    </inertial>
    <visual>
      <origin
        xyz="0 0 0"
        rpy="0 0 0" />
      <geometry>
        <mesh
          filename="package://BRAZO_ROBOT_URDF/meshes/ESLABON ROTACION.STL" />
      </geometry>
      <material
        name="">
        <color
          rgba="1 1 1 1" />
      </material>
    </visual>
    <collision>
      <origin
        xyz="0 0 0"
        rpy="0 0 0" />
      <geometry>
        <mesh
          filename="package://BRAZO_ROBOT_URDF/meshes/ESLABON ROTACION.STL" />
      </geometry>
    </collision>
  </link>
  <joint
    name="ESLABON ROTACION"
    type="revolute">
    <origin
      xyz="0 0 0"
      rpy="0 0 0" />
    <parent
      link="eslabon base" />
    <child
      link="ESLABON ROTACION" />
    <axis
      xyz="0 0 -1" />
    <limit
      lower="-1.5708"
      upper="1.5708"
      effort="0.18"
      velocity="10.472" />
    <dynamics
      damping="0"
      friction="0" />
  </joint>
  <link
    name="ESLABON DE BRAZO 1">
    <inertial>
      <origin
        xyz="-0.000966415503477563 -0.0190572854817526 0.00105821743021271"
        rpy="0 0 0" />
      <mass
        value="0.0485744385999758" />
      <inertia
        ixx="1.8593970179839E-05"
        ixy="-5.25312085428344E-07"
        ixz="-1.31826405070508E-07"
        iyy="3.2725311613632E-06"
        iyz="1.54876095792427E-06"
        izz="1.9702766411215E-05" />
    </inertial>
    <visual>
      <origin
        xyz="0 0 0"
        rpy="0 0 0" />
      <geometry>
        <mesh
          filename="package://BRAZO_ROBOT_URDF/meshes/ESLABON DE BRAZO 1.STL" />
      </geometry>
      <material
        name="">
        <color
          rgba="1 1 1 1" />
      </material>
    </visual>
    <collision>
      <origin
        xyz="0 0 0"
        rpy="0 0 0" />
      <geometry>
        <mesh
          filename="package://BRAZO_ROBOT_URDF/meshes/ESLABON DE BRAZO 1.STL" />
      </geometry>
    </collision>
  </link>
  <joint
    name="ESLABON DE BRAZO 1"
    type="revolute">
    <origin
      xyz="0 0 0.075"
      rpy="-1.5708 0 0" />
    <parent
      link="ESLABON ROTACION" />
    <child
      link="ESLABON DE BRAZO 1" />
    <axis
      xyz="0 0 -1" />
    <limit
      lower="-1.5708"
      upper="1.5708"
      effort="0.18"
      velocity="10.472" />
    <dynamics
      damping="0"
      friction="0" />
  </joint>
  <link
    name="ESLABON DE BRAZO 2">
    <inertial>
      <origin
        xyz="0.000301769617941816 0.0299293457414871 -0.000556617692094648"
        rpy="0 0 0" />
      <mass
        value="0.028486686920439" />
      <inertia
        ixx="1.51704938602305E-05"
        ixy="-1.96328794398074E-08"
        ixz="-5.85124985696709E-08"
        iyy="1.87208865570457E-06"
        iyz="-2.12186863467087E-07"
        izz="1.59205662534004E-05" />
    </inertial>
    <visual>
      <origin
        xyz="0 0 0"
        rpy="0 0 0" />
      <geometry>
        <mesh
          filename="package://BRAZO_ROBOT_URDF/meshes/ESLABON DE BRAZO 2.STL" />
      </geometry>
      <material
        name="">
        <color
          rgba="1 1 1 1" />
      </material>
    </visual>
    <collision>
      <origin
        xyz="0 0 0"
        rpy="0 0 0" />
      <geometry>
        <mesh
          filename="package://BRAZO_ROBOT_URDF/meshes/ESLABON DE BRAZO 2.STL" />
      </geometry>
    </collision>
  </link>
  <joint
    name="ESLABON DE BRAZO 2"
    type="revolute">
    <origin
      xyz="0 -0.06 0"
      rpy="0 0 -1.5708" />
    <parent
      link="ESLABON DE BRAZO 1" />
    <child
      link="ESLABON DE BRAZO 2" />
    <axis
      xyz="0 0 -1" />
    <limit
      lower="-1.5708"
      upper="1.5708"
      effort="0.18"
      velocity="10.472" />
    <dynamics
      damping="0"
      friction="0" />
  </joint>
  <link
    name="ESLABON BASE GRIPPER">
    <inertial>
      <origin
        xyz="-0.00104217230985984 3.44390048610879E-05 0.0812317135361134"
        rpy="0 0 0" />
      <mass
        value="0.00437816277547282" />
      <inertia
        ixx="3.85346965709011E-07"
        ixy="4.83674876889536E-10"
        ixz="5.56015541469149E-08"
        iyy="3.84305888855166E-07"
        iyz="-1.8373758114991E-09"
        izz="1.93040520057411E-07" />
    </inertial>
    <visual>
      <origin
        xyz="0 0 0"
        rpy="0 0 0" />
      <geometry>
        <mesh
          filename="package://BRAZO_ROBOT_URDF/meshes/ESLABON BASE GRIPPER.STL" />
      </geometry>
      <material
        name="">
        <color
          rgba="1 1 1 1" />
      </material>
    </visual>
    <collision>
      <origin
        xyz="0 0 0"
        rpy="0 0 0" />
      <geometry>
        <mesh
          filename="package://BRAZO_ROBOT_URDF/meshes/ESLABON BASE GRIPPER.STL" />
      </geometry>
    </collision>
  </link>
  <joint
    name="ESLABON BASE GRIPPER"
    type="revolute">
    <origin
      xyz="0 0 0"
      rpy="-1.5708 0 0" />
    <parent
      link="ESLABON DE BRAZO 2" />
    <child
      link="ESLABON BASE GRIPPER" />
    <axis
      xyz="0 0 -1" />
    <limit
      lower="-1.5708"
      upper="1.5708"
      effort="0.18"
      velocity="10.472" />
    <dynamics
      damping="0"
      friction="0" />
  </joint>
  <link
    name="GRIPPER IZQUIERDO">
    <inertial>
      <origin
        xyz="0.00240614947711461 -0.0127077067381982 -0.000750000000000417"
        rpy="0 0 0" />
      <mass
        value="0.000157968134836279" />
      <inertia
        ixx="1.21356317394437E-08"
        ixy="-1.37850376181E-09"
        ixz="-2.15336814443922E-22"
        iyy="1.15154867314015E-09"
        iyz="-3.860596359656E-22"
        izz="1.32287224011962E-08" />
    </inertial>
    <visual>
      <origin
        xyz="0 0 0"
        rpy="0 0 0" />
      <geometry>
        <mesh
          filename="package://BRAZO_ROBOT_URDF/meshes/GRIPPER IZQUIERDO.STL" />
      </geometry>
      <material
        name="">
        <color
          rgba="1 1 1 1" />
      </material>
    </visual>
    <collision>
      <origin
        xyz="0 0 0"
        rpy="0 0 0" />
      <geometry>
        <mesh
          filename="package://BRAZO_ROBOT_URDF/meshes/GRIPPER IZQUIERDO.STL" />
      </geometry>
    </collision>
  </link>
  <joint
    name="GRIPPER DERECHO"
    type="revolute">
    <origin
      xyz="0 -0.0036696 0.099465"
      rpy="-1.5708 0 -1.5708" />
    <parent
      link="ESLABON BASE GRIPPER" />
    <child
      link="GRIPPER IZQUIERDO" />
    <axis
      xyz="0 0 -1" />
    <limit
      lower="0"
      upper="1.5708"
      effort="0.18"
      velocity="10.472" />
    <dynamics
      damping="0"
      friction="0" />
  </joint>
  <link
    name="GRIPPER DERECHO">
    <inertial>
      <origin
        xyz="0.00248564370729545 -0.0126923969844406 0.000750000000000028"
        rpy="0 0 0" />
      <mass
        value="0.000157968134836293" />
      <inertia
        ixx="1.21524579984785E-08"
        ixy="-1.30964440647263E-09"
        ixz="-1.18565610904285E-22"
        iyy="1.13472241410606E-09"
        iyz="6.141240697254E-23"
        izz="1.32287224011969E-08" />
    </inertial>
    <visual>
      <origin
        xyz="0 0 0"
        rpy="0 0 0" />
      <geometry>
        <mesh
          filename="package://BRAZO_ROBOT_URDF/meshes/GRIPPER DERECHO.STL" />
      </geometry>
      <material
        name="">
        <color
          rgba="1 1 1 1" />
      </material>
    </visual>
    <collision>
      <origin
        xyz="0 0 0"
        rpy="0 0 0" />
      <geometry>
        <mesh
          filename="package://BRAZO_ROBOT_URDF/meshes/GRIPPER DERECHO.STL" />
      </geometry>
    </collision>
  </link>
  <joint
    name="GRIPPER DERECHO"
    type="revolute">
    <origin
      xyz="0 0.0039504 0.099465"
      rpy="-1.5708 0 1.5708" />
    <parent
      link="ESLABON BASE GRIPPER" />
    <child
      link="GRIPPER DERECHO" />
    <axis
      xyz="0 0 1" />
    <limit
      lower="0"
      upper="1.5708"
      effort="0.18"
      velocity="10.472" />
    <dynamics
      damping="0"
      friction="0" />
  </joint>
</robot>